Workbook

Sheet Dashboard
A1: RETAIL SALES PERFORMANCE DASHBOARD
A2: FY2024 - FY2026 | Select filters below to update every figure and chart instantly
A4: FILTERS (interactive slicer-style controls)
B5: Region: | C5: All | E5: Salesperson: | F5: All | H5: Product: | I5: All | K5: Year: | L5: All
A7: TOTAL REVENUE (Rs.) | D7: TOTAL UNITS SOLD | G7: TRANSACTIONS | J7: AVG ORDER VALUE (Rs.)
A8: {=_xlfn.SUMIFS('Cleaned Data'!G1:G1001,'Cleaned Data'!B1:B1001,IF(C5="All","*",C5),'Cleaned Data'!C1:C1001,IF(F5="All","*",F5),'Cleaned Data'!D1:D1001,IF(I5="All","*",I5),'Cleaned Data'!H1:H1001,IF(L5="All",">0",L5))} -> 425458945 | D8: {=_xlfn.SUMIFS('Cleaned Data'!E1:E1001,'Cleaned Data'!B1:B1001,IF(C5="All","*",C5),'Cleaned Data'!C1:C1001,IF(F5="All","*",F5),'Cleaned Data'!D1:D1001,IF(I5="All","*",I5),'Cleaned Data'!H1:H1001,IF(L5="All",">0",L5))} -> 10103 | G8: {=_xlfn.COUNTIFS('Cleaned Data'!B1:B1001,IF(C5="All","*",C5),'Cleaned Data'!C1:C1001,IF(F5="All","*",F5),'Cleaned Data'!D1:D1001,IF(I5="All","*",I5),'Cleaned Data'!H1:H1001,IF(L5="All",">0",L5))} -> 1000 | J8: {=_xlfn.IFERROR(A8/G8,0)} -> 425458.95
A9: FILTERED PERFORMANCE VIEWS
P10: Product | Q10: Revenue
P11: Phone | Q11: {=_xlfn.SUMIFS('Cleaned Data'!G1:G1001,'Cleaned Data'!B1:B1001,IF(C6="All","*",C6),'Cleaned Data'!C1:C1001,IF(F6="All","*",F6),'Cleaned Data'!D1:D1001,P11,'Cleaned Data'!H1:H1001,IF(L6="All",">0",L6))} -> 0
P12: Accessory | Q12: {=_xlfn.SUMIFS('Cleaned Data'!G1:G1001,'Cleaned Data'!B1:B1001,IF(C6="All","*",C6),'Cleaned Data'!C1:C1001,IF(F6="All","*",F6),'Cleaned Data'!D1:D1001,P12,'Cleaned Data'!H1:H1001,IF(L6="All",">0",L6))} -> 0
P13: Laptop | Q13: {=_xlfn.SUMIFS('Cleaned Data'!G1:G1001,'Cleaned Data'!B1:B1001,IF(C6="All","*",C6),'Cleaned Data'!C1:C1001,IF(F6="All","*",F6),'Cleaned Data'!D1:D1001,P13,'Cleaned Data'!H1:H1001,IF(L6="All",">0",L6))} -> 0
P14: Tablet | Q14: {=_xlfn.SUMIFS('Cleaned Data'!G1:G1001,'Cleaned Data'!B1:B1001,IF(C6="All","*",C6),'Cleaned Data'!C1:C1001,IF(F6="All","*",F6),'Cleaned Data'!D1:D1001,P14,'Cleaned Data'!H1:H1001,IF(L6="All",">0",L6))} -> 0
P16: Region | Q16: Revenue
P17: North | Q17: {=_xlfn.SUMIFS('Cleaned Data'!G1:G1001,'Cleaned Data'!C1:C1001,IF(F6="All","*",F6),'Cleaned Data'!D1:D1001,IF(I6="All","*",I6),'Cleaned Data'!H1:H1001,IF(L6="All",">0",L6),'Cleaned Data'!B1:B1001,P17)} -> 0
P18: South | Q18: {=_xlfn.SUMIFS('Cleaned Data'!G1:G1001,'Cleaned Data'!C1:C1001,IF(F6="All","*",F6),'Cleaned Data'!D1:D1001,IF(I6="All","*",I6),'Cleaned Data'!H1:H1001,IF(L6="All",">0",L6),'Cleaned Data'!B1:B1001,P18)} -> 0
P19: East | Q19: {=_xlfn.SUMIFS('Cleaned Data'!G1:G1001,'Cleaned Data'!C1:C1001,IF(F6="All","*",F6),'Cleaned Data'!D1:D1001,IF(I6="All","*",I6),'Cleaned Data'!H1:H1001,IF(L6="All",">0",L6),'Cleaned Data'!B1:B1001,P19)} -> 0
P20: West | Q20: {=_xlfn.SUMIFS('Cleaned Data'!G1:G1001,'Cleaned Data'!C1:C1001,IF(F6="All","*",F6),'Cleaned Data'!D1:D1001,IF(I6="All","*",I6),'Cleaned Data'!H1:H1001,IF(L6="All",">0",L6),'Cleaned Data'!B1:B1001,P20)} -> 0
P22: Month | Q22: Revenue
P23: Jan-2024 | Q23: {=_xlfn.SUMIFS('Cleaned Data'!G1:G1001,'Cleaned Data'!B1:B1001,IF(C6="All","*",C6),'Cleaned Data'!C1:C1001,IF(F6="All","*",F6),'Cleaned Data'!D1:D1001,IF(I6="All","*",I6),'Cleaned Data'!J1:J1001,P23)} -> 0
P24: Feb-2024 | Q24: {=_xlfn.SUMIFS('Cleaned Data'!G1:G1001,'Cleaned Data'!B1:B1001,IF(C6="All","*",C6),'Cleaned Data'!C1:C1001,IF(F6="All","*",F6),'Cleaned Data'!D1:D1001,IF(I6="All","*",I6),'Cleaned Data'!J1:J1001,P24)} -> 0
P25: Mar-2024 | Q25: {=_xlfn.SUMIFS('Cleaned Data'!G1:G1001,'Cleaned Data'!B1:B1001,IF(C6="All","*",C6),'Cleaned Data'!C1:C1001,IF(F6="All","*",F6),'Cleaned Data'!D1:D1001,IF(I6="All","*",I6),'Cleaned Data'!J1:J1001,P25)} -> 0
P26: Apr-2024 | Q26: {=_xlfn.SUMIFS('Cleaned Data'!G1:G1001,'Cleaned Data'!B1:B1001,IF(C6="All","*",C6),'Cleaned Data'!C1:C1001,IF(F6="All","*",F6),'Cleaned Data'!D1:D1001,IF(I6="All","*",I6),'Cleaned Data'!J1:J1001,P26)} -> 0
P27: May-2024 | Q27: {=_xlfn.SUMIFS('Cleaned Data'!G1:G1001,'Cleaned Data'!B1:B1001,IF(C6="All","*",C6),'Cleaned Data'!C1:C1001,IF(F6="All","*",F6),'Cleaned Data'!D1:D1001,IF(I6="All","*",I6),'Cleaned Data'!J1:J1001,P27)} -> 0
A28: TOP PERFORMERS - OVERALL (ALL DATA, NOT FILTERED) | P28: Jun-2024 | Q28: {=_xlfn.SUMIFS('Cleaned Data'!G1:G1001,'Cleaned Data'!B1:B1001,IF(C6="All","*",C6),'Cleaned Data'!C1:C1001,IF(F6="All","*",F6),'Cleaned Data'!D1:D1001,IF(I6="All","*",I6),'Cleaned Data'!J1:J1001,P28)} -> 0
A29: Rank | B29: Top Salespersons | C29: Revenue (Rs.) | F29: Rank | G29: Top Products | H29: Revenue (Rs.) | P29: Jul-2024 | Q29: {=_xlfn.SUMIFS('Cleaned Data'!G1:G1001,'Cleaned Data'!B1:B1001,IF(C6="All","*",C6),'Cleaned Data'!C1:C1001,IF(F6="All","*",F6),'Cleaned Data'!D1:D1001,IF(I6="All","*",I6),'Cleaned Data'!J1:J1001,P29)} -> 0
A30: {='Top Performers'!A6} -> 1 | B30: {='Top Performers'!B6} -> Priya | C30: {='Top Performers'!C6} -> 80332014 | F30: {='Top Performers'!A14} -> 1 | G30: {='Top Performers'!B14} -> Accessory | H30: {='Top Performers'!C14} -> 110115331 | P30: Aug-2024 | Q30: {=_xlfn.SUMIFS('Cleaned Data'!G1:G1001,'Cleaned Data'!B1:B1001,IF(C6="All","*",C6),'Cleaned Data'!C1:C1001,IF(F6="All","*",F6),'Cleaned Data'!D1:D1001,IF(I6="All","*",I6),'Cleaned Data'!J1:J1001,P30)} -> 0
A31: {='Top Performers'!A7} -> 2 | B31: {='Top Performers'!B7} -> Karan | C31: {='Top Performers'!C7} -> 73021096 | F31: {='Top Performers'!A15} -> 2 | G31: {='Top Performers'!B15} -> Phone | H31: {='Top Performers'!C15} -> 108974946 | P31: Sep-2024 | Q31: {=_xlfn.SUMIFS('Cleaned Data'!G1:G1001,'Cleaned Data'!B1:B1001,IF(C6="All","*",C6),'Cleaned Data'!C1:C1001,IF(F6="All","*",F6),'Cleaned Data'!D1:D1001,IF(I6="All","*",I6),'Cleaned Data'!J1:J1001,P31)} -> 0
A32: {='Top Performers'!A8} -> 3 | B32: {='Top Performers'!B8} -> Sneha | C32: {='Top Performers'!C8} -> 72443697 | F32: {='Top Performers'!A16} -> 3 | G32: {='Top Performers'!B16} -> Tablet | H32: {='Top Performers'!C16} -> 104126322 | P32: Oct-2024 | Q32: {=_xlfn.SUMIFS('Cleaned Data'!G1:G1001,'Cleaned Data'!B1:B1001,IF(C6="All","*",C6),'Cleaned Data'!C1:C1001,IF(F6="All","*",F6),'Cleaned Data'!D1:D1001,IF(I6="All","*",I6),'Cleaned Data'!J1:J1001,P32)} -> 0
A33: {='Top Performers'!A9} -> 4 | B33: {='Top Performers'!B9} -> Neha | C33: {='Top Performers'!C9} -> 68554411 | F33: {='Top Performers'!A17} -> 4 | G33: {='Top Performers'!B17} -> Laptop | H33: {='Top Performers'!C17} -> 102242346 | P33: Nov-2024 | Q33: {=_xlfn.SUMIFS('Cleaned Data'!G1:G1001,'Cleaned Data'!B1:B1001,IF(C6="All","*",C6),'Cleaned Data'!C1:C1001,IF(F6="All","*",F6),'Cleaned Data'!D1:D1001,IF(I6="All","*",I6),'Cleaned Data'!J1:J1001,P33)} -> 0
A34: {='Top Performers'!A10} -> 5 | B34: {='Top Performers'!B10} -> Amit | C34: {='Top Performers'!C10} -> 67691309 | P34: Dec-2024 | Q34: {=_xlfn.SUMIFS('Cleaned Data'!G1:G1001,'Cleaned Data'!B1:B1001,IF(C6="All","*",C6),'Cleaned Data'!C1:C1001,IF(F6="All","*",F6),'Cleaned Data'!D1:D1001,IF(I6="All","*",I6),'Cleaned Data'!J1:J1001,P34)} -> 0
P35: Jan-2025 | Q35: {=_xlfn.SUMIFS('Cleaned Data'!G1:G1001,'Cleaned Data'!B1:B1001,IF(C6="All","*",C6),'Cleaned Data'!C1:C1001,IF(F6="All","*",F6),'Cleaned Data'!D1:D1001,IF(I6="All","*",I6),'Cleaned Data'!J1:J1001,P35)} -> 0
P36: Feb-2025 | Q36: {=_xlfn.SUMIFS('Cleaned Data'!G1:G1001,'Cleaned Data'!B1:B1001,IF(C6="All","*",C6),'Cleaned Data'!C1:C1001,IF(F6="All","*",F6),'Cleaned Data'!D1:D1001,IF(I6="All","*",I6),'Cleaned Data'!J1:J1001,P36)} -> 0
P37: Mar-2025 | Q37: {=_xlfn.SUMIFS('Cleaned Data'!G1:G1001,'Cleaned Data'!B1:B1001,IF(C6="All","*",C6),'Cleaned Data'!C1:C1001,IF(F6="All","*",F6),'Cleaned Data'!D1:D1001,IF(I6="All","*",I6),'Cleaned Data'!J1:J1001,P37)} -> 0
P38: Apr-2025 | Q38: {=_xlfn.SUMIFS('Cleaned Data'!G1:G1001,'Cleaned Data'!B1:B1001,IF(C6="All","*",C6),'Cleaned Data'!C1:C1001,IF(F6="All","*",F6),'Cleaned Data'!D1:D1001,IF(I6="All","*",I6),'Cleaned Data'!J1:J1001,P38)} -> 0
P39: May-2025 | Q39: {=_xlfn.SUMIFS('Cleaned Data'!G1:G1001,'Cleaned Data'!B1:B1001,IF(C6="All","*",C6),'Cleaned Data'!C1:C1001,IF(F6="All","*",F6),'Cleaned Data'!D1:D1001,IF(I6="All","*",I6),'Cleaned Data'!J1:J1001,P39)} -> 0
P40: Jun-2025 | Q40: {=_xlfn.SUMIFS('Cleaned Data'!G1:G1001,'Cleaned Data'!B1:B1001,IF(C6="All","*",C6),'Cleaned Data'!C1:C1001,IF(F6="All","*",F6),'Cleaned Data'!D1:D1001,IF(I6="All","*",I6),'Cleaned Data'!J1:J1001,P40)} -> 0
P41: Jul-2025 | Q41: {=_xlfn.SUMIFS('Cleaned Data'!G1:G1001,'Cleaned Data'!B1:B1001,IF(C6="All","*",C6),'Cleaned Data'!C1:C1001,IF(F6="All","*",F6),'Cleaned Data'!D1:D1001,IF(I6="All","*",I6),'Cleaned Data'!J1:J1001,P41)} -> 0
P42: Aug-2025 | Q42: {=_xlfn.SUMIFS('Cleaned Data'!G1:G1001,'Cleaned Data'!B1:B1001,IF(C6="All","*",C6),'Cleaned Data'!C1:C1001,IF(F6="All","*",F6),'Cleaned Data'!D1:D1001,IF(I6="All","*",I6),'Cleaned Data'!J1:J1001,P42)} -> 0
P43: Sep-2025 | Q43: {=_xlfn.SUMIFS('Cleaned Data'!G1:G1001,'Cleaned Data'!B1:B1001,IF(C6="All","*",C6),'Cleaned Data'!C1:C1001,IF(F6="All","*",F6),'Cleaned Data'!D1:D1001,IF(I6="All","*",I6),'Cleaned Data'!J1:J1001,P43)} -> 0
P44: Oct-2025 | Q44: {=_xlfn.SUMIFS('Cleaned Data'!G1:G1001,'Cleaned Data'!B1:B1001,IF(C6="All","*",C6),'Cleaned Data'!C1:C1001,IF(F6="All","*",F6),'Cleaned Data'!D1:D1001,IF(I6="All","*",I6),'Cleaned Data'!J1:J1001,P44)} -> 0
...

Sheet Cleaned Data
A1: Date | B1: Region | C1: Salesperson | D1: Product | E1: Units Sold | F1: Unit Price (Rs.) | G1: Revenue (Rs.) | H1: Year | I1: Quarter | J1: Month
A2: 45292 | B2: North | C2: Priya | D2: Phone | E2: 16 | F2: 39217 | G2: {=E2*F2} -> 627472 | H2: {=YEAR(A2)} -> 2024 | I2: {="Q"&ROUNDUP(MONTH(A2)/3,0)} -> Q1 | J2: Jan-2024
A3: 45293 | B3: North | C3: Karan | D3: Accessory | E3: 12 | F3: 32048 | G3: {=E3*F3} -> 384576 | H3: {=YEAR(A3)} -> 2024 | I3: {="Q"&ROUNDUP(MONTH(A3)/3,0)} -> Q1 | J3: Jan-2024
A4: 45293 | B4: South | C4: Amit | D4: Laptop | E4: 11 | F4: 37821 | G4: {=E4*F4} -> 416031 | H4: {=YEAR(A4)} -> 2024 | I4: {="Q"&ROUNDUP(MONTH(A4)/3,0)} -> Q1 | J4: Jan-2024
A5: 45293 | B5: North | C5: Amit | D5: Phone | E5: 9 | F5: 74212 | G5: {=E5*F5} -> 667908 | H5: {=YEAR(A5)} -> 2024 | I5: {="Q"&ROUNDUP(MONTH(A5)/3,0)} -> Q1 | J5: Jan-2024
A6: 45296 | B6: South | C6: Neha | D6: Accessory | E6: 14 | F6: 60863 | G6: {=E6*F6} -> 852082 | H6: {=YEAR(A6)} -> 2024 | I6: {="Q"&ROUNDUP(MONTH(A6)/3,0)} -> Q1 | J6: Jan-2024
A7: 45296 | B7: South | C7: Neha | D7: Accessory | E7: 13 | F7: 17356 | G7: {=E7*F7} -> 225628 | H7: {=YEAR(A7)} -> 2024 | I7: {="Q"&ROUNDUP(MONTH(A7)/3,0)} -> Q1 | J7: Jan-2024
A8: 45299 | B8: South | C8: Neha | D8: Phone | E8: 19 | F8: 52929 | G8: {=E8*F8} -> 1005651 | H8: {=YEAR(A8)} -> 2024 | I8: {="Q"&ROUNDUP(MONTH(A8)/3,0)} -> Q1 | J8: Jan-2024
A9: 45300 | B9: East | C9: Sneha | D9: Tablet | E9: 3 | F9: 56493 | G9: {=E9*F9} -> 169479 | H9: {=YEAR(A9)} -> 2024 | I9: {="Q"&ROUNDUP(MONTH(A9)/3,0)} -> Q1 | J9: Jan-2024
A10: 45300 | B10: South | C10: Sneha | D10: Laptop | E10: 17 | F10: 38722 | G10: {=E10*F10} -> 658274 | H10: {=YEAR(A10)} -> 2024 | I10: {="Q"&ROUNDUP(MONTH(A10)/3,0)} -> Q1 | J10: Jan-2024
A11: 45301 | B11: North | C11: Priya | D11: Accessory | E11: 16 | F11: 15589 | G11: {=E11*F11} -> 249424 | H11: {=YEAR(A11)} -> 2024 | I11: {="Q"&ROUNDUP(MONTH(A11)/3,0)} -> Q1 | J11: Jan-2024
A12: 45303 | B12: South | C12: Priya | D12: Laptop | E12: 18 | F12: 38885 | G12: {=E12*F12} -> 699930 | H12: {=YEAR(A12)} -> 2024 | I12: {="Q"&ROUNDUP(MONTH(A12)/3,0)} -> Q1 | J12: Jan-2024
A13: 45303 | B13: North | C13: Neha | D13: Accessory | E13: 15 | F13: 15283 | G13: {=E13*F13} -> 229245 | H13: {=YEAR(A13)} -> 2024 | I13: {="Q"&ROUNDUP(MONTH(A13)/3,0)} -> Q1 | J13: Jan-2024
... A1001: 46290 | B1001: West | C1001: Neha | D1001: Accessory | E1001: 3 | F1001: 59353 | G1001: {=E1001*F1001} -> 178059 | H1001: {=YEAR(A1001)} -> 2026 | I1001: {="Q"&ROUNDUP(MONTH(A1001)/3,0)} -> Q3 | J1001: Sep-2026

Sheet Top Performers
A1: Top Performers Analysis
A2: Ranked by total revenue generated across the full dataset
J3: Helper: All Salespersons (unranked)
A4: Top 5 Salespersons by Revenue | J4: Salesperson | K4: Revenue | L4: Units | M4: Transactions | N4: Avg Order Value
A5: Rank | B5: Salesperson | C5: Revenue (Rs.) | D5: Units Sold | E5: Transactions | F5: Avg Order Value (Rs.) | G5: Revenue Share % | J5: Priya | K5: {=SUMIF('Cleaned Data'!C1:C1001,J5,'Cleaned Data'!G1:G1001)} -> 80332014 | L5: {=SUMIF('Cleaned Data'!C1:C1001,J5,'Cleaned Data'!E1:E1001)} -> 1836 | M5: {=COUNTIF('Cleaned Data'!C1:C1001,J5)} -> 173 | N5: {=K5/M5} -> 464346.9
A6: 1 | B6: {=INDEX($J$5:$J$10,MATCH(C6,$K$5:$K$10,0))} -> Priya | C6: {=LARGE($K$5:$K$10,A6)} -> 80332014 | D6: {=INDEX($L$5:$L$10,MATCH(C6,$K$5:$K$10,0))} -> 1836 | E6: {=INDEX($M$5:$M$10,MATCH(C6,$K$5:$K$10,0))} -> 173 | F6: {=C6/E6} -> 464346.9 | G6: {=C6/SUM($K$5:$K$10)} -> 0.18881261 | J6: Karan | K6: {=SUMIF('Cleaned Data'!C1:C1001,J6,'Cleaned Data'!G1:G1001)} -> 73021096 | L6: {=SUMIF('Cleaned Data'!C1:C1001,J6,'Cleaned Data'!E1:E1001)} -> 1679 | M6: {=COUNTIF('Cleaned Data'!C1:C1001,J6)} -> 172 | N6: {=K6/M6} -> 424541.26
A7: 2 | B7: {=INDEX($J$5:$J$10,MATCH(C7,$K$5:$K$10,0))} -> Karan | C7: {=LARGE($K$5:$K$10,A7)} -> 73021096 | D7: {=INDEX($L$5:$L$10,MATCH(C7,$K$5:$K$10,0))} -> 1679 | E7: {=INDEX($M$5:$M$10,MATCH(C7,$K$5:$K$10,0))} -> 172 | F7: {=C7/E7} -> 424541.26 | G7: {=C7/SUM($K$5:$K$10)} -> 0.17162901 | J7: Amit | K7: {=SUMIF('Cleaned Data'!C1:C1001,J7,'Cleaned Data'!G1:G1001)} -> 67691309 | L7: {=SUMIF('Cleaned Data'!C1:C1001,J7,'Cleaned Data'!E1:E1001)} -> 1705 | M7: {=COUNTIF('Cleaned Data'!C1:C1001,J7)} -> 164 | N7: {=K7/M7} -> 412751.88
A8: 3 | B8: {=INDEX($J$5:$J$10,MATCH(C8,$K$5:$K$10,0))} -> Sneha | C8: {=LARGE($K$5:$K$10,A8)} -> 72443697 | D8: {=INDEX($L$5:$L$10,MATCH(C8,$K$5:$K$10,0))} -> 1739 | E8: {=INDEX($M$5:$M$10,MATCH(C8,$K$5:$K$10,0))} -> 178 | F8: {=C8/E8} -> 406987.06 | G8: {=C8/SUM($K$5:$K$10)} -> 0.17027189 | J8: Neha | K8: {=SUMIF('Cleaned Data'!C1:C1001,J8,'Cleaned Data'!G1:G1001)} -> 68554411 | L8: {=SUMIF('Cleaned Data'!C1:C1001,J8,'Cleaned Data'!E1:E1001)} -> 1641 | M8: {=COUNTIF('Cleaned Data'!C1:C1001,J8)} -> 164 | N8: {=K8/M8} -> 418014.7
A9: 4 | B9: {=INDEX($J$5:$J$10,MATCH(C9,$K$5:$K$10,0))} -> Neha | C9: {=LARGE($K$5:$K$10,A9)} -> 68554411 | D9: {=INDEX($L$5:$L$10,MATCH(C9,$K$5:$K$10,0))} -> 1641 | E9: {=INDEX($M$5:$M$10,MATCH(C9,$K$5:$K$10,0))} -> 164 | F9: {=C9/E9} -> 418014.7 | G9: {=C9/SUM($K$5:$K$10)} -> 0.1611305 | J9: Sneha | K9: {=SUMIF('Cleaned Data'!C1:C1001,J9,'Cleaned Data'!G1:G1001)} -> 72443697 | L9: {=SUMIF('Cleaned Data'!C1:C1001,J9,'Cleaned Data'!E1:E1001)} -> 1739 | M9: {=COUNTIF('Cleaned Data'!C1:C1001,J9)} -> 178 | N9: {=K9/M9} -> 406987.06
A10: 5 | B10: {=INDEX($J$5:$J$10,MATCH(C10,$K$5:$K$10,0))} -> Amit | C10: {=LARGE($K$5:$K$10,A10)} -> 67691309 | D10: {=INDEX($L$5:$L$10,MATCH(C10,$K$5:$K$10,0))} -> 1705 | E10: {=INDEX($M$5:$M$10,MATCH(C10,$K$5:$K$10,0))} -> 164 | F10: {=C10/E10} -> 412751.88 | G10: {=C10/SUM($K$5:$K$10)} -> 0.15910186 | J10: Rahul | K10: {=SUMIF('Cleaned Data'!C1:C1001,J10,'Cleaned Data'!G1:G1001)} -> 63416418 | L10: {=SUMIF('Cleaned Data'!C1:C1001,J10,'Cleaned Data'!E1:E1001)} -> 1503 | M10: {=COUNTIF('Cleaned Data'!C1:C1001,J10)} -> 149 | N10: {=K10/M10} -> 425613.54
A12: Top Products by Revenue (Note: dataset contains only 4 product categories) | J12: Helper: All Products (unranked)
A13: Rank | B13: Product | C13: Revenue (Rs.) | D13: Units Sold | E13: Transactions | F13: Avg Order Value (Rs.) | G13: Revenue Share % | J13: Product | K13: Revenue | L13: Units | M13: Transactions | N13: Avg Order Value
A14: 1 | B14: {=INDEX($J$14:$J$17,MATCH(C14,$K$14:$K$17,0))} -> Accessory | C14: {=LARGE($K$14:$K$17,A14)} -> 110115331 | D14: {=INDEX($L$14:$L$17,MATCH(C14,$K$14:$K$17,0))} -> 2587 | E14: {=INDEX($M$14:$M$17,MATCH(C14,$K$14:$K$17,0))} -> 272 | F14: {=C14/E14} -> 404835.78 | G14: {=C14/SUM($K$14:$K$17)} -> 0.25881541 | J14: Phone | K14: {=SUMIF('Cleaned Data'!D1:D1001,J14,'Cleaned Data'!G1:G1001)} -> 108974946 | L14: {=SUMIF('Cleaned Data'!D1:D1001,J14,'Cleaned Data'!E1:E1001)} -> 2700 | M14: {=COUNTIF('Cleaned Data'!D1:D1001,J14)} -> 254 | N14: {=K14/M14} -> 429035.22
A15: 2 | B15: {=INDEX($J$14:$J$17,MATCH(C15,$K$14:$K$17,0))} -> Phone | C15: {=LARGE($K$14:$K$17,A15)} -> 108974946 | D15: {=INDEX($L$14:$L$17,MATCH(C15,$K$14:$K$17,0))} -> 2700 | E15: {=INDEX($M$14:$M$17,MATCH(C15,$K$14:$K$17,0))} -> 254 | F15: {=C15/E15} -> 429035.22 | G15: {=C15/SUM($K$14:$K$17)} -> 0.25613504 | J15: Accessory | K15: {=SUMIF('Cleaned Data'!D1:D1001,J15,'Cleaned Data'!G1:G1001)} -> 110115331 | L15: {=SUMIF('Cleaned Data'!D1:D1001,J15,'Cleaned Data'!E1:E1001)} -> 2587 | M15: {=COUNTIF('Cleaned Data'!D1:D1001,J15)} -> 272 | N15: {=K15/M15} -> 404835.78
A16: 3 | B16: {=INDEX($J$14:$J$17,MATCH(C16,$K$14:$K$17,0))} -> Tablet | C16: {=LARGE($K$14:$K$17,A16)} -> 104126322 | D16: {=INDEX($L$14:$L$17,MATCH(C16,$K$14:$K$17,0))} -> 2411 | E16: {=INDEX($M$14:$M$17,MATCH(C16,$K$14:$K$17,0))} -> 227 | F16: {=C16/E16} -> 458706.26 | G16: {=C16/SUM($K$14:$K$17)} -> 0.24473882 | J16: Laptop | K16: {=SUMIF('Cleaned Data'!D1:D1001,J16,'Cleaned Data'!G1:G1001)} -> 102242346 | L16: {=SUMIF('Cleaned Data'!D1:D1001,J16,'Cleaned Data'!E1:E1001)} -> 2405 | M16: {=COUNTIF('Cleaned Data'!D1:D1001,J16)} -> 247 | N16: {=K16/M16} -> 413936.62
A17: 4 | B17: {=INDEX($J$14:$J$17,MATCH(C17,$K$14:$K$17,0))} -> Laptop | C17: {=LARGE($K$14:$K$17,A17)} -> 102242346 | D17: {=INDEX($L$14:$L$17,MATCH(C17,$K$14:$K$17,0))} -> 2405 | E17: {=INDEX($M$14:$M$17,MATCH(C17,$K$14:$K$17,0))} -> 247 | F17: {=C17/E17} -> 413936.62 | G17: {=C17/SUM($K$14:$K$17)} -> 0.24031072 | J17: Tablet | K17: {=SUMIF('Cleaned Data'!D1:D1001,J17,'Cleaned Data'!G1:G1001)} -> 104126322 | L17: {=SUMIF('Cleaned Data'!D1:D1001,J17,'Cleaned Data'!E1:E1001)} -> 2411 | M17: {=COUNTIF('Cleaned Data'!D1:D1001,J17)} -> 227 | N17: {=K17/M17} -> 458706.26

Sheet Monthly & Regional Trends
A1: Monthly & Regional Sales Trends
A2: All figures computed live from the Cleaned Data sheet
A4: Monthly Revenue & Units Trend
A5: Month | B5: Revenue (Rs.) | C5: Units Sold | D5: Transactions
A6: Jan-2024 | B6: {=SUMIF('Cleaned Data'!J1:J1001,A6,'Cleaned Data'!G1:G1001)} -> 13091344 | C6: {=SUMIF('Cleaned Data'!J1:J1001,A6,'Cleaned Data'!E1:E1001)} -> 316 | D6: {=COUNTIF('Cleaned Data'!J1:J1001,A6)} -> 30
A7: Feb-2024 | B7: {=SUMIF('Cleaned Data'!J1:J1001,A7,'Cleaned Data'!G1:G1001)} -> 14823394 | C7: {=SUMIF('Cleaned Data'!J1:J1001,A7,'Cleaned Data'!E1:E1001)} -> 336 | D7: {=COUNTIF('Cleaned Data'!J1:J1001,A7)} -> 35
A8: Mar-2024 | B8: {=SUMIF('Cleaned Data'!J1:J1001,A8,'Cleaned Data'!G1:G1001)} -> 8468568 | C8: {=SUMIF('Cleaned Data'!J1:J1001,A8,'Cleaned Data'!E1:E1001)} -> 198 | D8: {=COUNTIF('Cleaned Data'!J1:J1001,A8)} -> 20
A9: Apr-2024 | B9: {=SUMIF('Cleaned Data'!J1:J1001,A9,'Cleaned Data'!G1:G1001)} -> 13943225 | C9: {=SUMIF('Cleaned Data'!J1:J1001,A9,'Cleaned Data'!E1:E1001)} -> 344 | D9: {=COUNTIF('Cleaned Data'!J1:J1001,A9)} -> 34
A10: May-2024 | B10: {=SUMIF('Cleaned Data'!J1:J1001,A10,'Cleaned Data'!G1:G1001)} -> 10276242 | C10: {=SUMIF('Cleaned Data'!J1:J1001,A10,'Cleaned Data'!E1:E1001)} -> 254 | D10: {=COUNTIF('Cleaned Data'!J1:J1001,A10)} -> 33
A11: Jun-2024 | B11: {=SUMIF('Cleaned Data'!J1:J1001,A11,'Cleaned Data'!G1:G1001)} -> 14420530 | C11: {=SUMIF('Cleaned Data'!J1:J1001,A11,'Cleaned Data'!E1:E1001)} -> 346 | D11: {=COUNTIF('Cleaned Data'!J1:J1001,A11)} -> 31
A12: Jul-2024 | B12: {=SUMIF('Cleaned Data'!J1:J1001,A12,'Cleaned Data'!G1:G1001)} -> 12810483 | C12: {=SUMIF('Cleaned Data'!J1:J1001,A12,'Cleaned Data'!E1:E1001)} -> 317 | D12: {=COUNTIF('Cleaned Data'!J1:J1001,A12)} -> 31
A13: Aug-2024 | B13: {=SUMIF('Cleaned Data'!J1:J1001,A13,'Cleaned Data'!G1:G1001)} -> 13994409 | C13: {=SUMIF('Cleaned Data'!J1:J1001,A13,'Cleaned Data'!E1:E1001)} -> 336 | D13: {=COUNTIF('Cleaned Data'!J1:J1001,A13)} -> 37
A14: Sep-2024 | B14: {=SUMIF('Cleaned Data'!J1:J1001,A14,'Cleaned Data'!G1:G1001)} -> 14746979 | C14: {=SUMIF('Cleaned Data'!J1:J1001,A14,'Cleaned Data'!E1:E1001)} -> 327 | D14: {=COUNTIF('Cleaned Data'!J1:J1001,A14)} -> 31
A15: Oct-2024 | B15: {=SUMIF('Cleaned Data'!J1:J1001,A15,'Cleaned Data'!G1:G1001)} -> 10412407 | C15: {=SUMIF('Cleaned Data'!J1:J1001,A15,'Cleaned Data'!E1:E1001)} -> 248 | D15: {=COUNTIF('Cleaned Data'!J1:J1001,A15)} -> 24
A16: Nov-2024 | B16: {=SUMIF('Cleaned Data'!J1:J1001,A16,'Cleaned Data'!G1:G1001)} -> 6969279 | C16: {=SUMIF('Cleaned Data'!J1:J1001,A16,'Cleaned Data'!E1:E1001)} -> 131 | D16: {=COUNTIF('Cleaned Data'!J1:J1001,A16)} -> 15
A17: Dec-2024 | B17: {=SUMIF('Cleaned Data'!J1:J1001,A17,'Cleaned Data'!G1:G1001)} -> 12839766 | C17: {=SUMIF('Cleaned Data'!J1:J1001,A17,'Cleaned Data'!E1:E1001)} -> 297 | D17: {=COUNTIF('Cleaned Data'!J1:J1001,A17)} -> 30
A18: Jan-2025 | B18: {=SUMIF('Cleaned Data'!J1:J1001,A18,'Cleaned Data'!G1:G1001)} -> 19061653 | C18: {=SUMIF('Cleaned Data'!J1:J1001,A18,'Cleaned Data'!E1:E1001)} -> 405 | D18: {=COUNTIF('Cleaned Data'!J1:J1001,A18)} -> 39
A19: Feb-2025 | B19: {=SUMIF('Cleaned Data'!J1:J1001,A19,'Cleaned Data'!G1:G1001)} -> 11366242 | C19: {=SUMIF('Cleaned Data'!J1:J1001,A19,'Cleaned Data'!E1:E1001)} -> 328 | D19: {=COUNTIF('Cleaned Data'!J1:J1001,A19)} -> 30
A20: Mar-2025 | B20: {=SUMIF('Cleaned Data'!J1:J1001,A20,'Cleaned Data'!G1:G1001)} -> 9808736 | C20: {=SUMIF('Cleaned Data'!J1:J1001,A20,'Cleaned Data'!E1:E1001)} -> 230 | D20: {=COUNTIF('Cleaned Data'!J1:J1001,A20)} -> 24
A21: Apr-2025 | B21: {=SUMIF('Cleaned Data'!J1:J1001,A21,'Cleaned Data'!G1:G1001)} -> 16371228 | C21: {=SUMIF('Cleaned Data'!J1:J1001,A21,'Cleaned Data'!E1:E1001)} -> 371 | D21: {=COUNTIF('Cleaned Data'!J1:J1001,A21)} -> 32
A22: May-2025 | B22: {=SUMIF('Cleaned Data'!J1:J1001,A22,'Cleaned Data'!G1:G1001)} -> 16535409 | C22: {=SUMIF('Cleaned Data'!J1:J1001,A22,'Cleaned Data'!E1:E1001)} -> 399 | D22: {=COUNTIF('Cleaned Data'!J1:J1001,A22)} -> 40
A23: Jun-2025 | B23: {=SUMIF('Cleaned Data'!J1:J1001,A23,'Cleaned Data'!G1:G1001)} -> 6375553 | C23: {=SUMIF('Cleaned Data'!J1:J1001,A23,'Cleaned Data'!E1:E1001)} -> 170 | D23: {=COUNTIF('Cleaned Data'!J1:J1001,A23)} -> 17
A24: Jul-2025 | B24: {=SUMIF('Cleaned Data'!J1:J1001,A24,'Cleaned Data'!G1:G1001)} -> 14435147 | C24: {=SUMIF('Cleaned Data'!J1:J1001,A24,'Cleaned Data'!E1:E1001)} -> 371 | D24: {=COUNTIF('Cleaned Data'!J1:J1001,A24)} -> 36
A25: Aug-2025 | B25: {=SUMIF('Cleaned Data'!J1:J1001,A25,'Cleaned Data'!G1:G1001)} -> 8624025 | C25: {=SUMIF('Cleaned Data'!J1:J1001,A25,'Cleaned Data'!E1:E1001)} -> 201 | D25: {=COUNTIF('Cleaned Data'!J1:J1001,A25)} -> 18
A26: Sep-2025 | B26: {=SUMIF('Cleaned Data'!J1:J1001,A26,'Cleaned Data'!G1:G1001)} -> 12309760 | C26: {=SUMIF('Cleaned Data'!J1:J1001,A26,'Cleaned Data'!E1:E1001)} -> 320 | D26: {=COUNTIF('Cleaned Data'!J1:J1001,A26)} -> 28
A27: Oct-2025 | B27: {=SUMIF('Cleaned Data'!J1:J1001,A27,'Cleaned Data'!G1:G1001)} -> 18273456 | C27: {=SUMIF('Cleaned Data'!J1:J1001,A27,'Cleaned Data'!E1:E1001)} -> 409 | D27: {=COUNTIF('Cleaned Data'!J1:J1001,A27)} -> 42
A28: Nov-2025 | B28: {=SUMIF('Cleaned Data'!J1:J1001,A28,'Cleaned Data'!G1:G1001)} -> 16366844 | C28: {=SUMIF('Cleaned Data'!J1:J1001,A28,'Cleaned Data'!E1:E1001)} -> 394 | D28: {=COUNTIF('Cleaned Data'!J1:J1001,A28)} -> 39
A29: Dec-2025 | B29: {=SUMIF('Cleaned Data'!J1:J1001,A29,'Cleaned Data'!G1:G1001)} -> 12506851 | C29: {=SUMIF('Cleaned Data'!J1:J1001,A29,'Cleaned Data'!E1:E1001)} -> 258 | D29: {=COUNTIF('Cleaned Data'!J1:J1001,A29)} -> 25
A30: Jan-2026 | B30: {=SUMIF('Cleaned Data'!J1:J1001,A30,'Cleaned Data'!G1:G1001)} -> 14750263 | C30: {=SUMIF('Cleaned Data'!J1:J1001,A30,'Cleaned Data'!E1:E1001)} -> 323 | D30: {=COUNTIF('Cleaned Data'!J1:J1001,A30)} -> 34
A31: Feb-2026 | B31: {=SUMIF('Cleaned Data'!J1:J1001,A31,'Cleaned Data'!G1:G1001)} -> 13112174 | C31: {=SUMIF('Cleaned Data'!J1:J1001,A31,'Cleaned Data'!E1:E1001)} -> 262 | D31: {=COUNTIF('Cleaned Data'!J1:J1001,A31)} -> 28
A32: Mar-2026 | B32: {=SUMIF('Cleaned Data'!J1:J1001,A32,'Cleaned Data'!G1:G1001)} -> 13101015 | C32: {=SUMIF('Cleaned Data'!J1:J1001,A32,'Cleaned Data'!E1:E1001)} -> 360 | D32: {=COUNTIF('Cleaned Data'!J1:J1001,A32)} -> 35
A33: Apr-2026 | B33: {=SUMIF('Cleaned Data'!J1:J1001,A33,'Cleaned Data'!G1:G1001)} -> 12040328 | C33: {=SUMIF('Cleaned Data'!J1:J1001,A33,'Cleaned Data'!E1:E1001)} -> 312 | D33: {=COUNTIF('Cleaned Data'!J1:J1001,A33)} -> 31
A34: May-2026 | B34: {=SUMIF('Cleaned Data'!J1:J1001,A34,'Cleaned Data'!G1:G1001)} -> 12989579 | C34: {=SUMIF('Cleaned Data'!J1:J1001,A34,'Cleaned Data'!E1:E1001)} -> 373 | D34: {=COUNTIF('Cleaned Data'!J1:J1001,A34)} -> 36
A35: Jun-2026 | B35: {=SUMIF('Cleaned Data'!J1:J1001,A35,'Cleaned Data'!G1:G1001)} -> 13383989 | C35: {=SUMIF('Cleaned Data'!J1:J1001,A35,'Cleaned Data'!E1:E1001)} -> 340 | D35: {=COUNTIF('Cleaned Data'!J1:J1001,A35)} -> 29
A36: Jul-2026 | B36: {=SUMIF('Cleaned Data'!J1:J1001,A36,'Cleaned Data'!G1:G1001)} -> 12338414 | C36: {=SUMIF('Cleaned Data'!J1:J1001,A36,'Cleaned Data'!E1:E1001)} -> 284 | D36: {=COUNTIF('Cleaned Data'!J1:J1001,A36)} -> 29
A37: Aug-2026 | B37: {=SUMIF('Cleaned Data'!J1:J1001,A37,'Cleaned Data'!G1:G1001)} -> 17483959 | C37: {=SUMIF('Cleaned Data'!J1:J1001,A37,'Cleaned Data'!E1:E1001)} -> 369 | D37: {=COUNTIF('Cleaned Data'!J1:J1001,A37)} -> 37
A38: Sep-2026 | B38: {=SUMIF('Cleaned Data'!J1:J1001,A38,'Cleaned Data'!G1:G1001)} -> 7427694 | C38: {=SUMIF('Cleaned Data'!J1:J1001,A38,'Cleaned Data'!E1:E1001)} -> 174 | D38: {=COUNTIF('Cleaned Data'!J1:J1001,A38)} -> 20
A40: Regional Performance Summary
A41: Region | B41: Revenue (Rs.) | C41: Units Sold | D41: Transactions | E41: Avg Order Value (Rs.)
A42: North | B42: {=SUMIF('Cleaned Data'!B1:B1001,A42,'Cleaned Data'!G1:G1001)} -> 116561640 | C42: {=SUMIF('Cleaned Data'!B1:B1001,A42,'Cleaned Data'!E1:E1001)} -> 2756 | D42: {=COUNTIF('Cleaned Data'!B1:B1001,A42)} -> 264 | E42: {=B42/D42} -> 441521.36
...

Sheet Insights & Recommendations
A1: INSIGHTS & RECOMMENDATIONS
A2: Retail Sales Data Analysis | Period: Jan 2024 - Sep 2026
A4: Executive Summary
A5: The dataset covers 1,000 transactions recorded between January 2024 and September 2026, generating total revenue of Rs. 42.55 crore (Rs. 425,458,945) across 10,103 units sold. Revenue is broadly balanced across regions, product categories and the sales team, with the strongest region (North) and the strongest performer (Priya) each holding roughly a fifth of total revenue - indicating a healthy, non-concentrated business rather than dependence on a single driver.
A7: Data Cleaning Summary
A8: • Source file contained 1,000 records across 7 fields (Date, Region, Salesperson, Product, Units Sold, Unit Price, Revenue); no missing values or duplicate rows were found.
A9: • An empty, unlabeled helper column left over from the original export was identified and removed.
A10: • Text fields (Region, Salesperson, Product) were trimmed of extra spaces and standardized to consistent capitalization to prevent duplicate categories (e.g. "north" vs "North").
A11: • Revenue was recalculated as Units Sold x Unit Price using a live formula for every row, confirming 100% consistency with the original figures and making the sheet self-auditing going forward.
A12: • Records were sorted chronologically and Year, Quarter and Month fields were added to support time-based analysis.
A14: Key Findings - Top Performers
A15: • Priya is the top-performing salesperson with Rs. 8.03 crore in revenue (18.9% of the total), followed closely by Karan (17.2%) and Sneha (17.0%). The gap between the top and bottom performer is under 4 percentage points, showing consistent performance across the team rather than one standout outlier.
... A38: • Dashboard: one-page summary with Region, Salesperson, Product and Year drop-down filters at the top - change any of them and the KPI cards and all three charts update automatically, giving slicer-style interactivity.
